(dp1
S'output'
p2
S"<type 'exceptions.MemoryError'> "
p3
sS'layer'
p4
S'C:\\Users\\unificace\\unificace\\web2py\\applications\\init\\models\\db.py'
p5
sS'code'
p6
S'<code object <module> at 0000000001F9F7B0, file "C:\\Users\\unificace\\unificace\\web2py\\applications\\init\\models\\db.py", line 14>'
p7
sS'snapshot'
p8
(dp9
sS'traceback'
p10
S'Traceback (most recent call last):\n  File ".\\gluon\\restricted.py", line 219, in restricted\n    exec(ccode, environment)\n  File "C:\\Users\\unificace\\unificace\\web2py\\applications\\init\\models\\db.py", line 365, in <module>\n    this_utg=db(db.auth_user.username==utg_user_id).select(db.auth_user.id)#if user already exist in auth_user table\n  File "C:\\Users\\unificace\\unificace\\web2py\\gluon\\packages\\dal\\pydal\\objects.py", line 2250, in select\n    return adapter.select(self.query, fields, attributes)\n  File "C:\\Users\\unificace\\unificace\\web2py\\gluon\\packages\\dal\\pydal\\adapters\\base.py", line 762, in select\n  File "C:\\Users\\unificace\\unificace\\web2py\\gluon\\packages\\dal\\pydal\\adapters\\base.py", line 741, in _select_aux\n    return processor(rows, fields, colnames, cacheable=cacheable)\n  File "C:\\Users\\unificace\\unificace\\web2py\\gluon\\packages\\dal\\pydal\\adapters\\base.py", line 308, in parse\n    fields=fields)\n  File "C:\\Users\\unificace\\unificace\\web2py\\gluon\\packages\\dal\\pydal\\objects.py", line 2666, in __init__\nMemoryError\n'
p11
s.