(dp1
S'output'
p2
S'<type \'exceptions.RuntimeError\'> Failure to connect, tried 5 times:\nTraceback (most recent call last):\n  File "C:\\Users\\unificace\\unificace\\web2py\\gluon\\packages\\dal\\pydal\\base.py", line 454, in __init__\n    self._adapter = adapter(**kwargs)\n  File "C:\\Users\\unificace\\unificace\\web2py\\gluon\\packages\\dal\\pydal\\adapters\\__init__.py", line 40, in __call__\n    obj = super(AdapterMeta, cls).__call__(*args, **kwargs)\n  File "C:\\Users\\unificace\\unificace\\web2py\\gluon\\packages\\dal\\pydal\\adapters\\mssql.py", line 31, in __init__\n    driver_args, adapter_args, do_connect, after_connection)\n  File "C:\\Users\\unificace\\unificace\\web2py\\gluon\\packages\\dal\\pydal\\adapters\\base.py", line 368, in __init__\n    super(SQLAdapter, self).__init__(*args, **kwargs)\n  File "C:\\Users\\unificace\\unificace\\web2py\\gluon\\packages\\dal\\pydal\\adapters\\base.py", line 52, in __init__\n    self.reconnect()\n  File "C:\\Users\\unificace\\unificace\\web2py\\gluon\\packages\\dal\\pydal\\connection.py", line 172, in reconnect\n    self.connection = self.connector()\n  File "C:\\Users\\unificace\\unificace\\web2py\\gluon\\packages\\dal\\pydal\\adapters\\mssql.py", line 81, in connector\n    return self.driver.connect(self.cnxn, **self.driver_args)\n  File ".\\gluon\\contrib\\pypyodbc.py", line 2434, in __init__\n    self.connect(connectString, autocommit, ansi, timeout, unicode_results, readonly)\n  File ".\\gluon\\contrib\\pypyodbc.py", line 2483, in connect\n    check_success(self, ret)\n  File ".\\gluon\\contrib\\pypyodbc.py", line 988, in check_success\n    ctrl_err(SQL_HANDLE_DBC, ODBC_obj.dbc_h, ret, ODBC_obj.ansi)\n  File ".\\gluon\\contrib\\pypyodbc.py", line 966, in ctrl_err\n    raise DatabaseError(state,err_text)\nDatabaseError: (u\'08001\', u\'[08001] [Microsoft][ODBC SQL Server Driver][DBNETLIB]SQL Server does not exist or access denied.\')\n'
p3
sS'layer'
p4
S'C:\\Users\\unificace\\unificace\\web2py\\applications\\init\\models\\db.py'
p5
sS'code'
p6
S'<code object <module> at 0000000002BCB730, file "C:\\Users\\unificace\\unificace\\web2py\\applications\\init\\models\\db.py", line 14>'
p7
sS'snapshot'
p8
(dp9
sS'traceback'
p10
S'Traceback (most recent call last):\n  File ".\\gluon\\restricted.py", line 219, in restricted\n    exec(ccode, environment)\n  File "C:\\Users\\unificace\\unificace\\web2py\\applications\\init\\models\\db.py", line 40, in <module>\n    check_reserved=[\'all\'])\n  File "C:\\Users\\unificace\\unificace\\web2py\\gluon\\packages\\dal\\pydal\\base.py", line 169, in __call__\n    obj = super(MetaDAL, cls).__call__(*args, **kwargs)\n  File "C:\\Users\\unificace\\unificace\\web2py\\gluon\\packages\\dal\\pydal\\base.py", line 474, in __init__\n    "Failure to connect, tried %d times:\\n%s" % (attempts, tb)\nRuntimeError: Failure to connect, tried 5 times:\nTraceback (most recent call last):\n  File "C:\\Users\\unificace\\unificace\\web2py\\gluon\\packages\\dal\\pydal\\base.py", line 454, in __init__\n    self._adapter = adapter(**kwargs)\n  File "C:\\Users\\unificace\\unificace\\web2py\\gluon\\packages\\dal\\pydal\\adapters\\__init__.py", line 40, in __call__\n    obj = super(AdapterMeta, cls).__call__(*args, **kwargs)\n  File "C:\\Users\\unificace\\unificace\\web2py\\gluon\\packages\\dal\\pydal\\adapters\\mssql.py", line 31, in __init__\n    driver_args, adapter_args, do_connect, after_connection)\n  File "C:\\Users\\unificace\\unificace\\web2py\\gluon\\packages\\dal\\pydal\\adapters\\base.py", line 368, in __init__\n    super(SQLAdapter, self).__init__(*args, **kwargs)\n  File "C:\\Users\\unificace\\unificace\\web2py\\gluon\\packages\\dal\\pydal\\adapters\\base.py", line 52, in __init__\n    self.reconnect()\n  File "C:\\Users\\unificace\\unificace\\web2py\\gluon\\packages\\dal\\pydal\\connection.py", line 172, in reconnect\n    self.connection = self.connector()\n  File "C:\\Users\\unificace\\unificace\\web2py\\gluon\\packages\\dal\\pydal\\adapters\\mssql.py", line 81, in connector\n    return self.driver.connect(self.cnxn, **self.driver_args)\n  File ".\\gluon\\contrib\\pypyodbc.py", line 2434, in __init__\n    self.connect(connectString, autocommit, ansi, timeout, unicode_results, readonly)\n  File ".\\gluon\\contrib\\pypyodbc.py", line 2483, in connect\n    check_success(self, ret)\n  File ".\\gluon\\contrib\\pypyodbc.py", line 988, in check_success\n    ctrl_err(SQL_HANDLE_DBC, ODBC_obj.dbc_h, ret, ODBC_obj.ansi)\n  File ".\\gluon\\contrib\\pypyodbc.py", line 966, in ctrl_err\n    raise DatabaseError(state,err_text)\nDatabaseError: (u\'08001\', u\'[08001] [Microsoft][ODBC SQL Server Driver][DBNETLIB]SQL Server does not exist or access denied.\')\n\n'
p11
s.